Workbook
Name Slicer_Deal_Status: #N/A
Name Slicer_Region: #N/A

Sheet pivot 1
A3: Row Labels | B3: Sum of Revenue
A4: P001 | B4: 51062.4
A5: P002 | B5: 0
A6: P003 | B6: 0
A7: P004 | B7: 248472.9
A8: P007 | B8: 413500
A9: P008 | B9: 0
A10: P010 | B10: 404070
A11: P011 | B11: 0
A12: P012 | B12: 74176
A13: P013 | B13: 253880
A14: P017 | B14: 56176
A15: P020 | B15: 286499.2
... A38: Grand Total | B38: 5145784.5

Sheet pivot 2
A3: Region | B3: Sum of Revenue
A4: Central | B4: 985974.4
A5: East | B5: 1280794.6
A6: North | B6: 1035795.3
A7: South | B7: 0
A8: West | B8: 1843220.2
A9: Grand Total | B9: 5145784.5

Sheet pivot 3
A3: Salespeoples name | B3: Sum of Revenue
A4: Salesperson 12 | B4: 442924.2
A5: Salesperson 13 | B5: 460246
A6: Salesperson 14 | B6: 157939.2
A7: Salesperson 16 | B7: 0
A8: Salesperson 17 | B8: 67413.5
A9: Salesperson 18 | B9: 112109.5
A10: Salesperson 19 | B10: 574610.4
A11: Salesperson 20 | B11: 0
A12: Salesperson 21 | B12: 53849.8
A13: Salesperson 22 | B13: 0
A14: Salesperson 23 | B14: 0
A15: Salesperson 24 | B15: 538498
... A32: Grand Total | B32: 5145784.5

Sheet pivot 4
A3: Row Labels | B3: Sum of Revenue
A4: Enterprise | B4: 270787.9
A5: Mid- Market | B5: 762982.8
A6: Mid-Market | B6: 1926188.1
A7: SME | B7: 1230545.9
A8: Startup | B8: 955279.75
A9: Grand Total | B9: 5145784.5

Sheet pivot5
B3: Column Labels
B4: Jan | C4: Feb | D4: Mar | E4: Apr | F4: May | G4: Jun | H4: Grand Total
A6: Sum of Revenue | B6: 1147660 | C6: 357695.6 | D6: 274946.75 | E6: 1885449.9 | F6: 839578.3 | G6: 640454 | H6: 5145784.5

Sheet pivot6
A3: Row Labels | B3: Sum of Revenue
A4: Software Product 26 | B4: 784564.2
A5: Software Product 37 | B5: 592347.8
A6: Software Product 29 | B6: 561267.35
A7: Software Product 7 | B7: 413500
A8: Software Product 10 | B8: 404070
A9: Grand Total | B9: 2755749.4

Sheet Sales Dashboard 
D1: ALAUKIK SALES DASHBOARD
A4: TOTAL REVENUE | B4: WON REVENUE | C4: TOTAL DEALS | D4: WON DEALS | E4: WIN RATE | V4: REGION | W4: REVENUE | Y4: Products | Z4: Revenue
A5: =SUM(Sales!I2:I51) -> 5145784.5 | B5: =SUMIF(Sales!F2:F51,"Won", Sales!I2:I51) -> 5145784.5 | C5: =COUNTA(Sales!A2:A51) -> 50 | D5: =COUNTIF(Sales!F2:F51, "Won") -> 29 | E5: =COUNTIF(Sales!F2:F51,"Won")/COUNTA(Sales!A2:A51) -> 0.58 | V5: North | W5: =SUMIF(Sales!K2:K50, V5, Sales!I2:I50) -> 1194843.9 | Y5: Software Product 24 | Z5: =SUMIF(Sales!N26:N75,Y5,Sales!I26:I75) -> 538498
V6: South | W6: =SUMIF(Sales!K2:K51, V6, Sales!I2:I51) -> 0 | Y6: Software Product 16 | Z6: =SUMIF(Sales!N3:N52,Y6,Sales!I3:I52) -> 417452
V7: East | W7: =SUMIF(Sales!K3:K52, V7, Sales!I3:I52) -> 1216884.1 | Y7: Software Product 7 | Z7: =SUMIF(Sales!N2:N51,Y7,Sales!I2:I51) -> 209953.8
A8: Select Region | B8: South | C8: REVENUE WON BY REGION | D8: SUM PRODUCT REVENUE | V8: West | W8: =SUMIF(Sales!K4:K53, V8, Sales!I4:I53) -> 830684.2 | Y8: Software Product 11 | Z8: =SUMIF(Sales!N9:N58,Y8,Sales!I9:I58) -> 157939.2
C9: =SUMIFS(Sales!I2:I50,Sales!F2:F50,"Won",Sales!K2:K50,B8) -> 625437.6 | D9: {=SUMPRODUCT((Sales!F2:F50="Won")*(Sales!K2:K50=B8)*Sales!I2:I50)} -> 625437.6 | Y9: Software Product 17 | Z9: =SUMIF(Sales!N7:N56,Y9,Sales!I7:I56) -> 157158.4
Y10: Software Product 14 | Z10: =SUMIF(Sales!N4:N53,Y10,Sales!I4:I53) -> 112109.5
Y11: Software Product 8 | Z11: =SUMIF(Sales!N15:N64,Y11,Sales!I15:I64) -> 104018.4
Y12: Software Product 5 | Z12: =SUMIF(Sales!N13:N62,Y12,Sales!I13:I62) -> 74518
A13: DYNAMIC TOP-N | B13: 2 | C13: =LARGE(pivot6!B4:B8,B13) -> 592347.8 | Y13: Software Product 13 | Z13: =SUMIF(Sales!N19:N68,Y13,Sales!I19:I68) -> 67413.5
Y14: Software Product 6 | Z14: =SUMIF(Sales!N14:N63,Y14,Sales!I14:I63) -> 54434
Y15: Software Product 19 | Z15: =SUMIF(Sales!N6:N55,Y15,Sales!I6:I55) -> 53849.8
Y16: Software Product 30 | Z16: =SUMIF(Sales!N30:N79,Y16,Sales!I30:I79) -> 51272
Y17: Software Product 31 | Z17: =SUMIF(Sales!N31:N80,Y17,Sales!I31:I80) -> 48594.4
Y18: Software Product 4 | Z18: =SUMIF(Sales!N5:N54,Y18,Sales!I5:I54) -> 22315
Y19: Software Product 26 | Z19: =SUMIF(Sales!N2:N50,Y19,Sales!I2:I50) -> 0
Y20: Software Product 27 | Z20: =SUMIF(Sales!N8:N57,Y20,Sales!I8:I57) -> 0
Y21: Software Product 1 | Z21: =SUMIF(Sales!N10:N59,Y21,Sales!I10:I59) -> 0
Y22: Software Product 2 | Z22: =SUMIF(Sales!N11:N60,Y22,Sales!I11:I60) -> 0
Y23: Software Product 3 | Z23: =SUMIF(Sales!N12:N61,Y23,Sales!I12:I61) -> 0
Y24: Software Product 9 | Z24: =SUMIF(Sales!N16:N65,Y24,Sales!I16:I65) -> 56176
Y25: Software Product 10 | Z25: =SUMIF(Sales!N17:N66,Y25,Sales!I17:I66) -> 0
Y26: Software Product 12 | Z26: =SUMIF(Sales!N18:N67,Y26,Sales!I18:I67) -> 0
Y27: Software Product 15 | Z27: =SUMIF(Sales!N20:N69,Y27,Sales!I20:I69) -> 0
Y28: Software Product 18 | Z28: =SUMIF(Sales!N21:N70,Y28,Sales!I21:I70) -> 0
Y29: Software Product 20 | Z29: =SUMIF(Sales!N22:N71,Y29,Sales!I22:I71) -> 0
Y30: Software Product 21 | Z30: =SUMIF(Sales!N23:N72,Y30,Sales!I23:I72) -> 0
Y31: Software Product 22 | Z31: =SUMIF(Sales!N24:N73,Y31,Sales!I24:I73) -> 0
Y32: Software Product 23 | Z32: =SUMIF(Sales!N25:N74,Y32,Sales!I25:I74) -> 0
Y33: Software Product 25 | Z33: =SUMIF(Sales!N27:N76,Y33,Sales!I27:I76) -> 0
Y34: Software Product 28 | Z34: =SUMIF(Sales!N28:N77,Y34,Sales!I28:I77) -> 0
Y35: Software Product 29 | Z35: =SUMIF(Sales!N29:N78,Y35,Sales!I29:I78) -> 0

Sheet pivot 7
A3: Row Labels | B3: Sum of Revenue
A4: S012 | B4: 538498
A5: SP024 | B5: 538498
A6: S021 | B6: 422049.6
A7: SP035 | B7: 422049.6
A8: S036 | B8: 417452
A9: SP019 | B9: 417452
A10: S039 | B10: 413500
A11: SP007 | B11: 413500
A12: S018 | B12: 404070
A13: SP013 | B13: 404070
A14: S004 | B14: 286499.2
A15: SP049 | B15: 286499.2
... A104: Grand Total | B104: 5145784.5

Sheet Line Chart
A3: Row Labels | B3: Sum of Revenue
A4: Jan | B4: 1147660
A5: Feb | B5: 357695.6
A6: Mar | B6: 274946.75
A7: Apr | B7: 1885449.9
A8: May | B8: 839578.3
A9: Jun | B9: 640454
A10: Grand Total | B10: 5145784.5

Sheet Bar Chart 1
A3: Row Labels | B3: Sum of Revenue
A4: Software Product 26 | B4: 784564.2
A5: Software Product 37 | B5: 592347.8
A6: Software Product 29 | B6: 561267.35
A7: Software Product 7 | B7: 413500
A8: Software Product 10 | B8: 404070
A9: Software Product 50 | B9: 293668.2
A10: Software Product 20 | B10: 286499.2
A11: Software Product 13 | B11: 253880
A12: Software Product 4 | B12: 248472.9
A13: Software Product 46 | B13: 236384
A14: Software Product 24 | B14: 203388
A15: Software Product 21 | B15: 143008.25
... A38: Grand Total | B38: 5145784.5

Sheet Column Bar
A3: Row Labels | B3: Sum of Revenue
A4: West | B4: 1843220.2
A5: East | B5: 1280794.6
A6: North | B6: 1035795.3
A7: Central | B7: 985974.4
A8: South | B8: 0
A9: Grand Total | B9: 5145784.5

Sheet Donut Chart
A3: Row Labels | B3: Count of Sale_ID
A4: Lost | B4: 14
A5: Pending | B5: 7
A6: Won | B6: 29
A7: Grand Total | B7: 50

Sheet Bar Chart 2
A3: Row Labels | B3: Sum of Revenue
A4: Salesperson 35 | B4: 768445.85
A5: Salesperson 19 | B5: 574610.4
A6: Salesperson 24 | B6: 538498
A7: Salesperson 49 | B7: 522883.2
A8: Salesperson 13 | B8: 460246
A9: Grand Total | B9: 2864683.5

Sheet Sales
A1: Sale_ID | B1: Date | C1: Customer_ID | D1: Product_ID | E1: Salesperson_ID | F1: Deal_Status | G1: Quantity | H1: Discount | I1: Revenue | J1: Lost_Reason | K1: Region | L1: Salesperson_Name | M1: MM-YYYY | N1: Products Name
A2: S015 | B2: 46069 | C2: C028 | D2: P001 | E2: =_xlfn.XLOOKUP(L2, L2:L51, Salespeople!A3:A52) -> SP002 | F2: Won | G2: 9 | H2: 10 | I2: 51062.4 | K2: =_xlfn.XLOOKUP(E2,E2:E51, Salespeople!D11:D60) -> West | L2: Salesperson 2 | M2: =TEXT(B2,"mmm-yyyy") -> Feb-2026 | N2: =_xlfn.XLOOKUP(D2, D2:D51, Products!B40:B89) -> Software Product 39
A3: S026 | B3: 46169 | C3: C048 | D3: P002 | E3: =_xlfn.XLOOKUP(L3, L3:L52, Salespeople!A44:A93) -> SP043 | F3: Lost | G3: 8 | H3: 20 | I3: 0 | J3: Price Too High | K3: =_xlfn.XLOOKUP(E3,E3:E52, Salespeople!D49:D98) -> North | L3: Salesperson 43 | M3: =TEXT(B3,"mmm-yyyy") -> May-2026 | N3: =_xlfn.XLOOKUP(D3, D3:D52, Products!B19:B68) -> Software Product 18
A4: S014 | B4: 46116 | C4: C014 | D4: P003 | E4: =_xlfn.XLOOKUP(L4, L4:L53, Salespeople!A19:A68) -> SP018 | F4: Lost | G4: 15 | H4: 10 | I4: 0 | J4: No Budget | K4: =_xlfn.XLOOKUP(E4,E4:E53, Salespeople!D26:D75) -> East | L4: Salesperson 18 | M4: =TEXT(B4,"mmm-yyyy") -> Apr-2026 | N4: =_xlfn.XLOOKUP(D4, D4:D53, Products!B33:B82) -> Software Product 32
A5: S040 | B5: 46151 | C5: C019 | D5: P004 | E5: =_xlfn.XLOOKUP(L5, L5:L54, Salespeople!A39:A88) -> SP038 | F5: Won | G5: 13 | H5: 10 | I5: 248472.9 | K5: =_xlfn.XLOOKUP(E5,E5:E54, Salespeople!D44:D93) -> East | L5: Salesperson 38 | M5: =TEXT(B5,"mmm-yyyy") -> May-2026 | N5: =_xlfn.XLOOKUP(D5, D5:D54, Products!B29:B78) -> Software Product 28
A6: S039 | B6: 46162 | C6: C010 | D6: P007 | E6: =_xlfn.XLOOKUP(L6, L6:L55, Salespeople!A41:A90) -> SP040 | F6: Won | G6: 20 | H6: 0 | I6: 413500 | K6: =_xlfn.XLOOKUP(E6,E6:E55, Salespeople!D46:D95) -> North | L6: Salesperson 40 | M6: =TEXT(B6,"mmm-yyyy") -> May-2026 | N6: =_xlfn.XLOOKUP(D6, D6:D55, Products!B3:B52) -> Software Product 2
A7: S032 | B7: 46080 | C7: C037 | D7: P008 | E7: =_xlfn.XLOOKUP(L7, L7:L56, Salespeople!A10:A59) -> SP009 | F7: Lost | G7: 18 | H7: 20 | I7: 0 | K7: =_xlfn.XLOOKUP(E7,E7:E56, Salespeople!D18:D67) -> North | L7: Salesperson 9 | M7: =TEXT(B7,"mmm-yyyy") -> Feb-2026 | N7: =_xlfn.XLOOKUP(D7, D7:D56, Products!B49:B98) -> Software Product 48
A8: S035 | B8: 46084 | C8: C005 | D8: P010 | E8: =_xlfn.XLOOKUP(L8, L8:L57, Salespeople!A12:A61) -> SP011 | F8: Pending | G8: 4 | H8: 10 | I8: 0 | K8: =_xlfn.XLOOKUP(E8,E8:E57, Salespeople!D20:D69) -> West | L8: Salesperson 11 | M8: =TEXT(B8,"mmm-yyyy") -> Mar-2026 | N8: =_xlfn.XLOOKUP(D8, D8:D57, Products!B42:B91) -> Software Product 41
A9: S049 | B9: 46111 | C9: C002 | D9: P010 | E9: =_xlfn.XLOOKUP(L9, L9:L58, Salespeople!A16:A65) -> SP015 | F9: Pending | G9: 15 | H9: 5 | I9: 0 | K9: =_xlfn.XLOOKUP(E9,E9:E58, Salespeople!D23:D72) -> Central | L9: Salesperson 15 | M9: =TEXT(B9,"mmm-yyyy") -> Mar-2026 | N9: =_xlfn.XLOOKUP(D9, D9:D58, Products!B26:B75) -> Software Product 25
A10: S018 | B10: 46190 | C10: C049 | D10: P010 | E10: =_xlfn.XLOOKUP(L10, L10:L59, Salespeople!A47:A96) -> SP046 | F10: Won | G10: 15 | H10: 0 | I10: 404070 | K10: =_xlfn.XLOOKUP(E10,E10:E59, Salespeople!D51:D100) -> East | L10: Salesperson 46 | M10: =TEXT(B10,"mmm-yyyy") -> Jun-2026 | N10: =_xlfn.XLOOKUP(D10, D10:D59, Products!B11:B60) -> Software Product 10
A11: S043 | B11: 46023 | C11: C005 | D11: P011 | E11: =_xlfn.XLOOKUP(L11, L11:L60, Salespeople!A2:A51) -> SP001 | F11: Lost | G11: 14 | H11: 15 | I11: 0 | K11: =_xlfn.XLOOKUP(E11,E11:E60, Salespeople!D2:D51) -> East | L11: Salesperson 1 | M11: =TEXT(B11,"mmm-yyyy") -> Jan-2026 | N11: =_xlfn.XLOOKUP(D11, D11:D60, Products!B16:B65) -> Software Product 15
A12: S006 | B12: 46075 | C12: C029 | D12: P012 | E12: =_xlfn.XLOOKUP(L12, L12:L61, Salespeople!A6:A55) -> SP005 | F12: Won | G12: 16 | H12: 0 | I12: 74176 | K12: =_xlfn.XLOOKUP(E12,E12:E61, Salespeople!D14:D63) -> North | L12: Salesperson 5 | M12: =TEXT(B12,"mmm-yyyy") -> Feb-2026 | N12: =_xlfn.XLOOKUP(D12, D12:D61, Products!B45:B94) -> Software Product 44
A13: S013 | B13: 46138 | C13: C029 | D13: P012 | E13: =_xlfn.XLOOKUP(L13, L13:L62, Salespeople!A29:A78) -> SP028 | F13: Lost | G13: 18 | H13: 0 | I13: 0 | J13: Competitor | K13: =_xlfn.XLOOKUP(E13,E13:E62, Salespeople!D35:D84) -> East | L13: Salesperson 28 | M13: =TEXT(B13,"mmm-yyyy") -> Apr-2026 | N13: =_xlfn.XLOOKUP(D13, D13:D62, Products!B23:B72) -> Software Product 22
A14: S023 | B14: 46146 | C14: C016 | D14: P012 | E14: =_xlfn.XLOOKUP(L14, L14:L63, Salespeople!A36:A85) -> SP035 | F14: Pending | G14: 12 | H14: 20 | I14: 0 | K14: =_xlfn.XLOOKUP(E14,E14:E63, Salespeople!D41:D90) -> West | L14: Salesperson 35 | M14: =TEXT(B14,"mmm-yyyy") -> May-2026 | N14: =_xlfn.XLOOKUP(D14, D14:D63, Products!B30:B79) -> Software Product 29
A15: S022 | B15: 46136 | C15: C012 | D15: P013 | E15: =_xlfn.XLOOKUP(L15, L15:L64, Salespeople!A28:A77) -> SP027 | F15: Won | G15: 11 | H15: 0 | I15: 253880 | K15: =_xlfn.XLOOKUP(E15,E15:E64, Salespeople!D34:D83) -> Central | L15: Salesperson 27 | M15: =TEXT(B15,"mmm-yyyy") -> Apr-2026 | N15: =_xlfn.XLOOKUP(D15, D15:D64, Products!B43:B92) -> Software Product 42
A16: S030 | B16: 46041 | C16: C033 | D16: P017 | E16: =_xlfn.XLOOKUP(L16, L16:L65, Salespeople!A49:A98) -> SP048 | F16: Won | G16: 4 | H16: 20 | I16: 56176 | K16: =_xlfn.XLOOKUP(E16,E16:E65, Salespeople!D8:D57) -> East | L16: Salesperson 48 | M16: =TEXT(B16,"mmm-yyyy") -> Jan-2026 | N16: =_xlfn.XLOOKUP(D16, D16:D65, Products!B10:B59) -> Software Product 9
A17: S004 | B17: 46123 | C17: C005 | D17: P020 | E17: =_xlfn.XLOOKUP(L17, L17:L66, Salespeople!A22:A71) -> SP021 | F17: Won | G17: 13 | H17: 20 | I17: 286499.2 | K17: =_xlfn.XLOOKUP(E17,E17:E66, Salespeople!D29:D78) -> North | L17: Salesperson 21 | M17: =TEXT(B17,"mmm-yyyy") -> Apr-2026 | N17: =_xlfn.XLOOKUP(D17, D17:D66, Products!B50:B99) -> Software Product 49
A18: S047 | B18: 46140 | C18: C024 | D18: P021 | E18: =_xlfn.XLOOKUP(L18, L18:L67, Salespeople!A32:A81) -> SP031 | F18: Won | G18: 19 | H18: 15 | I18: 143008.25 | K18: =_xlfn.XLOOKUP(E18,E18:E67, Salespeople!D38:D87) -> North | L18: Salesperson 31 | M18: =TEXT(B18,"mmm-yyyy") -> Apr-2026 | N18: =_xlfn.XLOOKUP(D18, D18:D67, Products!B37:B86) -> Software Product 36
A19: S029 | B19: 46085 | C19: C036 | D19: P023 | E19: =_xlfn.XLOOKUP(L19, L19:L68, Salespeople!A14:A63) -> SP013 | F19: Lost | G19: 8 | H19: 20 | I19: 0 | K19: =_xlfn.XLOOKUP(E19,E19:E68, Salespeople!D21:D70) -> East | L19: Salesperson 13 | M19: =TEXT(B19,"mmm-yyyy") -> Mar-2026 | N19: =_xlfn.XLOOKUP(D19, D19:D68, Products!B21:B70) -> Software Product 20
A20: S005 | B20: 46030 | C20: C022 | D20: P024 | E20: =_xlfn.XLOOKUP(L20, L20:L69, Salespeople!A35:A84) -> SP034 | F20: Won | G20: 15 | H20: 20 | I20: 203388 | K20: =_xlfn.XLOOKUP(E20,E20:E69, Salespeople!D5:D54) -> South | L20: Salesperson 34 | M20: =TEXT(B20,"mmm-yyyy") -> Jan-2026 | N20: =_xlfn.XLOOKUP(D20, D20:D69, Products!B34:B83) -> Software Product 33
A21: S046 | B21: 46148 | C21: C016 | D21: P025 | E21: =_xlfn.XLOOKUP(L21, L21:L70, Salespeople!A37:A86) -> SP036 | F21: Pending | G21: 18 | H21: 5 | I21: 0 | K21: =_xlfn.XLOOKUP(E21,E21:E70, Salespeople!D42:D91) -> Central | L21: Salesperson 36 | M21: =TEXT(B21,"mmm-yyyy") -> May-2026 | N21: =_xlfn.XLOOKUP(D21, D21:D70, Products!B2:B51) -> Software Product 1
A22: S031 | B22: 46114 | C22: C030 | D22: P026 | E22: =_xlfn.XLOOKUP(L22, L22:L71, Salespeople!A18:A67) -> SP017 | F22: Won | G22: 8 | H22: 20 | I22: 157158.4 | K22: =_xlfn.XLOOKUP(E22,E22:E71, Salespeople!D25:D74) -> East | L22: Salesperson 17 | M22: =TEXT(B22,"mmm-yyyy") -> Apr-2026 | N22: =_xlfn.XLOOKUP(D22, D22:D71, Products!B18:B67) -> Software Product 17
A23: S034 | B23: 46139 | C23: C010 | D23: P026 | E23: =_xlfn.XLOOKUP(L23, L23:L72, Salespeople!A30:A79) -> SP029 | F23: Won | G23: 9 | H23: 5 | I23: 209953.8 | K23: =_xlfn.XLOOKUP(E23,E23:E72, Salespeople!D36:D85) -> West | L23: Salesperson 29 | M23: =TEXT(B23,"mmm-yyyy") -> Apr-2026 | N23: =_xlfn.XLOOKUP(D23, D23:D72, Products!B8:B57) -> Software Product 7
A24: S036 | B24: 46045 | C24: C036 | D24: P026 | E24: =_xlfn.XLOOKUP(L24, L24:L73, Salespeople!A50:A99) -> SP049 | F24: Won | G24: 17 | H24: 0 | I24: 417452 | K24: =_xlfn.XLOOKUP(E24,E24:E73, Salespeople!D9:D58) -> Central | L24: Salesperson 49 | M24: =TEXT(B24,"mmm-yyyy") -> Jan-2026 | N24: =_xlfn.XLOOKUP(D24, D24:D73, Products!B17:B66) -> Software Product 16
A25: S003 | B25: 46076 | C25: C039 | D25: P027 | E25: =_xlfn.XLOOKUP(L25, L25:L74, Salespeople!A7:A56) -> SP006 | F25: Lost | G25: 13 | H25: 10 | I25: 0 | J25: Competitor | K25: =_xlfn.XLOOKUP(E25,E25:E74, Salespeople!D15:D64) -> Central | L25: Salesperson 6 | M25: =TEXT(B25,"mmm-yyyy") -> Feb-2026 | N25: =_xlfn.XLOOKUP(D25, D25:D74, Products!B36:B85) -> Software Product 35
A26: S001 | B26: 46092 | C26: C001 | D26: P028 | E26: =_xlfn.XLOOKUP(L26, L26:L75, Salespeople!A15:A64) -> SP014 | F26: Lost | G26: 6 | H26: 5 | I26: 0 | J26: No Budget | K26: =_xlfn.XLOOKUP(E26,E26:E75, Salespeople!D22:D71) -> East | L26: Salesperson 14 | M26: =TEXT(B26,"mmm-yyyy") -> Mar-2026 | N26: =_xlfn.XLOOKUP(D26, D26:D75, Products!B4:B53) -> Software Product 3
A27: S033 | B27: 46112 | C27: C023 | D27: P029 | E27: =_xlfn.XLOOKUP(L27, L27:L76, Salespeople!A17:A66) -> SP016 | F27: Won | G27: 5 | H27: 5 | I27: 139217.75 | K27: =_xlfn.XLOOKUP(E27,E27:E76, Salespeople!D24:D73) -> East | L27: Salesperson 16 | M27: =TEXT(B27,"mmm-yyyy") -> Mar-2026 | N27: =_xlfn.XLOOKUP(D27, D27:D76, Products!B39:B88) -> Software Product 38
A28: S021 | B28: 46035 | C28: C005 | D28: P029 | E28: =_xlfn.XLOOKUP(L28, L28:L77, Salespeople!A46:A95) -> SP045 | F28: Won | G28: 16 | H28: 10 | I28: 422049.6 | K28: =_xlfn.XLOOKUP(E28,E28:E77, Salespeople!D6:D55) -> South | L28: Salesperson 45 | M28: =TEXT(B28,"mmm-yyyy") -> Jan-2026 | N28: =_xlfn.XLOOKUP(D28, D28:D77, Products!B35:B84) -> Software Product 34
A29: S044 | B29: 46056 | C29: C045 | D29: P029 | E29: =_xlfn.XLOOKUP(L29, L29:L78, Salespeople!A51:A100) -> SP050 | F29: Lost | G29: 3 | H29: 0 | I29: 0 | K29: =_xlfn.XLOOKUP(E29,E29:E78, Salespeople!D10:D59) -> North | L29: Salesperson 50 | M29: =TEXT(B29,"mmm-yyyy") -> Feb-2026 | N29: =_xlfn.XLOOKUP(D29, D29:D78, Products!B44:B93) -> Software Product 43
A30: S024 | B30: 46128 | C30: C026 | D30: P031 | E30: =_xlfn.XLOOKUP(L30, L30:L79, Salespeople!A25:A74) -> SP024 | F30: Won | G30: 10 | H30: 15 | I30: 67413.5 | K30: =_xlfn.XLOOKUP(E30,E30:E79, Salespeople!D31:D80) -> North | L30: Salesperson 24 | M30: =TEXT(B30,"mmm-yyyy") -> Apr-2026 | N30: =_xlfn.XLOOKUP(D30, D30:D79, Products!B14:B63) -> Software Product 13
A31: S002 | B31: 46037 | C31: C016 | D31: P032 | E31: =_xlfn.XLOOKUP(L31, L31:L80, Salespeople!A48:A97) -> SP047 | F31: Lost | G31: 12 | H31: 5 | I31: 0 | J31: No Budget | K31: =_xlfn.XLOOKUP(E31,E31:E80, Salespeople!D7:D56) -> South | L31: Salesperson 47 | M31: =TEXT(B31,"mmm-yyyy") -> Jan-2026 | N31: =_xlfn.XLOOKUP(D31, D31:D80, Products!B24:B73) -> Software Product 23
A32: S009 | B32: 46027 | C32: C026 | D32: P033 | E32: =_xlfn.XLOOKUP(L32, L32:L81, Salespeople!A13:A62) -> SP012 | F32: Pending | G32: 4 | H32: 0 | I32: 0 | K32: =_xlfn.XLOOKUP(E32,E32:E81, Salespeople!D3:D52) -> North | L32: Salesperson 12 | M32: =TEXT(B32,"mmm-yyyy") -> Jan-2026 | N32: =_xlfn.XLOOKUP(D32, D32:D81, Products!B47:B96) -> Software Product 46
A33: S016 | B33: 46121 | C33: C005 | D33: P033 | E33: =_xlfn.XLOOKUP(L33, L33:L82, Salespeople!A21:A70) -> SP020 | F33: Won | G33: 17 | H33: 0 | I33: 54434 | K33: =_xlfn.XLOOKUP(E33,E33:E82, Salespeople!D28:D77) -> Central | L33: Salesperson 20 | M33: =TEXT(B33,"mmm-yyyy") -> Apr-2026 | N33: =_xlfn.XLOOKUP(D33, D33:D82, Products!B7:B56) -> Software Product 6
A34: S010 | B34: 46125 | C34: C016 | D34: P033 | E34: =_xlfn.XLOOKUP(L34, L34:L83, Salespeople!A23:A72) -> SP022 | F34: Won | G34: 3 | H34: 10 | I34: 8645.4 | K34: =_xlfn.XLOOKUP(E34,E34:E83, Salespeople!D30:D79) -> West | L34: Salesperson 22 | M34: =TEXT(B34,"mmm-yyyy") -> Apr-2026 | N34: =_xlfn.XLOOKUP(D34, D34:D83, Products!B41:B90) -> Software Product 40
A35: S037 | B35: 46149 | C35: C034 | D35: P034 | E35: =_xlfn.XLOOKUP(L35, L35:L84, Salespeople!A38:A87) -> SP037 | F35: Won | G35: 9 | H35: 20 | I35: 104018.4 | K35: =_xlfn.XLOOKUP(E35,E35:E84, Salespeople!D43:D92) -> Central | L35: Salesperson 37 | M35: =TEXT(B35,"mmm-yyyy") -> May-2026 | N35: =_xlfn.XLOOKUP(D35, D35:D84, Products!B9:B58) -> Software Product 8
A36: S008 | B36: 46130 | C36: C012 | D36: P035 | E36: =_xlfn.XLOOKUP(L36, L36:L85, Salespeople!A26:A75) -> SP025 | F36: Won | G36: 5 | H36: 5 | I36: 112109.5 | K36: =_xlfn.XLOOKUP(E36,E36:E85, Salespeople!D32:D81) -> Central | L36: Salesperson 25 | M36: =TEXT(B36,"mmm-yyyy") -> Apr-2026 | N36: =_xlfn.XLOOKUP(D36, D36:D85, Products!B15:B64) -> Software Product 14
A37: S028 | B37: 46142 | C37: C039 | D37: P035 | E37: =_xlfn.XLOOKUP(L37, L37:L86, Salespeople!A33:A82) -> SP032 | F37: Pending | G37: 12 | H37: 10 | I37: 0 | K37: =_xlfn.XLOOKUP(E37,E37:E86, Salespeople!D39:D88) -> North | L37: Salesperson 32 | M37: =TEXT(B37,"mmm-yyyy") -> Apr-2026 | N37: =_xlfn.XLOOKUP(D37, D37:D86, Products!B27:B76) -> Software Product 26
A38: S048 | B38: 46070 | C38: C016 | D38: P036 | E38: =_xlfn.XLOOKUP(L38, L38:L87, Salespeople!A4:A53) -> SP003 | F38: Won | G38: 5 | H38: 5 | I38: 74518 | K38: =_xlfn.XLOOKUP(E38,E38:E87, Salespeople!D12:D61) -> North | L38: Salesperson 3 | M38: =TEXT(B38,"mmm-yyyy") -> Feb-2026 | N38: =_xlfn.XLOOKUP(D38, D38:D87, Products!B6:B55) -> Software Product 5
A39: S045 | B39: 46118 | C39: C004 | D39: P036 | E39: =_xlfn.XLOOKUP(L39, L39:L88, Salespeople!A20:A69) -> SP019 | F39: Lost | G39: 6 | H39: 0 | I39: 0 | K39: =_xlfn.XLOOKUP(E39,E39:E88, Salespeople!D27:D76) -> South | L39: Salesperson 19 | M39: =TEXT(B39,"mmm-yyyy") -> Apr-2026 | N39: =_xlfn.XLOOKUP(D39, D39:D88, Products!B13:B62) -> Software Product 12
A40: S012 | B40: 46131 | C40: C022 | D40: P037 | E40: =_xlfn.XLOOKUP(L40, L40:L89, Salespeople!A27:A76) -> SP026 | F40: Won | G40: 20 | H40: 5 | I40: 538498 | K40: =_xlfn.XLOOKUP(E40,E40:E89, Salespeople!D33:D82) -> West | L40: Salesperson 26 | M40: =TEXT(B40,"mmm-yyyy") -> Apr-2026 | N40: =_xlfn.XLOOKUP(D40, D40:D89, Products!B25:B74) -> Software Product 24
...

Sheet lost deals analysis 
A1: Lost_Reason | B1: Number of Lost Deals
A2: Competitor | B2: =COUNTIFS(Sales!$F$2:$F$51,"Lost",Sales!$J$2:$J$51,A2) -> 5
A3: No Budget | B3: =COUNTIFS(Sales!$F$2:$F$51,"Lost",Sales!$J$2:$J$51,A3) -> 3
A4: Price Too High | B4: =COUNTIFS(Sales!$F$2:$F$51,"Lost",Sales!$J$2:$J$51,A4) -> 1

Sheet Win Rate Analysis 
A1: Salesperson_Name | B1: Won Deals | C1: Lost Deals | D1: Win Rate
A2: Salesperson 1 | B2: =COUNTIFS(Sales!$L$2:$L$51,A2,Sales!$F$2:$F$51,"Won") -> 0 | C2: =COUNTIFS(Sales!$L$2:$L$51,A2,Sales!$F$2:$F$51,"Lost") -> 1 | D2: =IFERROR(B2/(B2+C2),0) -> 0
A3: Salesperson 2 | B3: =COUNTIFS(Sales!$L$2:$L$51,A3,Sales!$F$2:$F$51,"Won") -> 1 | C3: =COUNTIFS(Sales!$L$2:$L$51,A3,Sales!$F$2:$F$51,"Lost") -> 0 | D3: =IFERROR(B3/(B3+C3),0) -> 1
A4: Salesperson 3 | B4: =COUNTIFS(Sales!$L$2:$L$51,A4,Sales!$F$2:$F$51,"Won") -> 1 | C4: =COUNTIFS(Sales!$L$2:$L$51,A4,Sales!$F$2:$F$51,"Lost") -> 0 | D4: =IFERROR(B4/(B4+C4),0) -> 1
A5: Salesperson 4 | B5: =COUNTIFS(Sales!$L$2:$L$51,A5,Sales!$F$2:$F$51,"Won") -> 0 | C5: =COUNTIFS(Sales!$L$2:$L$51,A5,Sales!$F$2:$F$51,"Lost") -> 1 | D5: =IFERROR(B5/(B5+C5),0) -> 0
A6: Salesperson 5 | B6: =COUNTIFS(Sales!$L$2:$L$51,A6,Sales!$F$2:$F$51,"Won") -> 1 | C6: =COUNTIFS(Sales!$L$2:$L$51,A6,Sales!$F$2:$F$51,"Lost") -> 0 | D6: =IFERROR(B6/(B6+C6),0) -> 1
A7: Salesperson 6 | B7: =COUNTIFS(Sales!$L$2:$L$51,A7,Sales!$F$2:$F$51,"Won") -> 0 | C7: =COUNTIFS(Sales!$L$2:$L$51,A7,Sales!$F$2:$F$51,"Lost") -> 1 | D7: =IFERROR(B7/(B7+C7),0) -> 0
A8: Salesperson 7 | B8: =COUNTIFS(Sales!$L$2:$L$51,A8,Sales!$F$2:$F$51,"Won") -> 0 | C8: =COUNTIFS(Sales!$L$2:$L$51,A8,Sales!$F$2:$F$51,"Lost") -> 1 | D8: =IFERROR(B8/(B8+C8),0) -> 0
A9: Salesperson 8 | B9: =COUNTIFS(Sales!$L$2:$L$51,A9,Sales!$F$2:$F$51,"Won") -> 1 | C9: =COUNTIFS(Sales!$L$2:$L$51,A9,Sales!$F$2:$F$51,"Lost") -> 0 | D9: =IFERROR(B9/(B9+C9),0) -> 1
A10: Salesperson 9 | B10: =COUNTIFS(Sales!$L$2:$L$51,A10,Sales!$F$2:$F$51,"Won") -> 0 | C10: =COUNTIFS(Sales!$L$2:$L$51,A10,Sales!$F$2:$F$51,"Lost") -> 1 | D10: =IFERROR(B10/(B10+C10),0) -> 0
A11: Salesperson 10 | B11: =COUNTIFS(Sales!$L$2:$L$51,A11,Sales!$F$2:$F$51,"Won") -> 1 | C11: =COUNTIFS(Sales!$L$2:$L$51,A11,Sales!$F$2:$F$51,"Lost") -> 0 | D11: =IFERROR(B11/(B11+C11),0) -> 1
A12: Salesperson 11 | B12: =COUNTIFS(Sales!$L$2:$L$51,A12,Sales!$F$2:$F$51,"Won") -> 0 | C12: =COUNTIFS(Sales!$L$2:$L$51,A12,Sales!$F$2:$F$51,"Lost") -> 0 | D12: =IFERROR(B12/(B12+C12),0) -> 0
A13: Salesperson 12 | B13: =COUNTIFS(Sales!$L$2:$L$51,A13,Sales!$F$2:$F$51,"Won") -> 0 | C13: =COUNTIFS(Sales!$L$2:$L$51,A13,Sales!$F$2:$F$51,"Lost") -> 0 | D13: =IFERROR(B13/(B13+C13),0) -> 0
... A50: Salesperson 49 | B50: =COUNTIFS(Sales!$L$2:$L$51,A50,Sales!$F$2:$F$51,"Won") -> 1 | C50: =COUNTIFS(Sales!$L$2:$L$51,A50,Sales!$F$2:$F$51,"Lost") -> 0 | D50: =IFERROR(B50/(B50+C50),0) -> 1
A51: Salesperson 50 | B51: =COUNTIFS(Sales!$L$2:$L$51,A51,Sales!$F$2:$F$51,"Won") -> 0 | C51: =COUNTIFS(Sales!$L$2:$L$51,A51,Sales!$F$2:$F$51,"Lost") -> 1 | D51: 0
B52: =SUM(B2:B51) -> 29 | C52: 14 | D52: =IFERROR(B50/(B52+C52),0) -> 0.023255814

Sheet Customers
A1: Customer_ID | B1: Customer_Name | C1: Industry | D1: Customer_Segment | E1: City | F1: State
A2: C001 | B2: Customer 1 | C2: Education | D2: Mid-Market | E2: Bengaluru | F2: Rajasthan
A3: C002 | B3: Customer 2 | C3: Retail | D3: Mid-Market | E3: Ahmedabad | F3: Telangana
A4: C003 | B4: Customer 3 | C4: Healthcare | D4: Mid-Market | E4: Bengaluru | F4: Delhi
A5: C004 | B5: Customer 4 | C5: Retail | D5: Enterprise | E5: Mumbai | F5: Karnataka
A6: C005 | B6: Customer 5 | C6: Retail | D6: Mid- Market | E6: Jaipur | F6: Rajasthan
A7: C006 | B7: Customer 6 | C7: Finance | D7: Enterprise | E7: Bengaluru | F7: Delhi
A8: C007 | B8: Customer 7 | C8: Healthcare | D8: Mid-Market | E8: Ahmedabad | F8: Delhi
A9: C008 | B9: Customer 8 | C9: Healthcare | D9: Startup | E9: Mumbai | F9: Madhya Pradesh
A10: C009 | B10: Customer 9 | C10: Healthcare | D10: Startup | E10: Indore | F10: Delhi
A11: C010 | B11: Customer 10 | C11: Retail | D11: SME | E11: Pune | F11: Telangana
A12: C011 | B12: Customer 11 | C12: Education | D12: Startup | E12: Pune | F12: Gujarat
... A51: C050 | B51: Customer 50 | C51: Education | D51: Startup | E51: Jaipur | F51: Karnataka

Sheet Products
A1: Product_ID | B1: Product_Name | C1: Category | D1: Price
A2: P001 | B2: Software Product 1 | C2: HR | D2: 6304
A3: P002 | B3: Software Product 2 | C3: HR | D3: 23147
A4: P003 | B4: Software Product 3 | C4: Cloud | D4: 24616
A5: P004 | B5: Software Product 4 | C5: Security | D5: 21237
A6: P005 | B6: Software Product 5 | C6: CRM | D6: 16808
A7: P006 | B7: Software Product 6 | C7: Cloud | D7: 9585
A8: P007 | B8: Software Product 7 | C8: Security | D8: 20675
A9: P008 | B9: Software Product 8 | C9: Analytics | D9: 22965
A10: P009 | B10: Software Product 9 | C10: Analytics | D10: 14649
A11: P010 | B11: Software Product 10 | C11: Analytics | D11: 26938
A12: P011 | B12: Software Product 11 | C12: Analytics | D12: 26664
A13: P012 | B13: Software Product 12 | C13: Analytics | D13: 4636
... A51: P050 | B51: Software Product 50 | C51: Support | D51: 12339

Sheet Salespeople
A1: Salesperson_ID | B1: Salesperson_Name | C1: Team | D1: Region | E1: Manager
A2: SP001 | B2: Salesperson 1 | C2: Mid-Market | D2: East | E2: Priya
A3: SP002 | B3: Salesperson 2 | C3: SMB | D3: North | E3: Amit
A4: SP003 | B4: Salesperson 3 | C4: Enterprise | D4: Central | E4: Priya
A5: SP004 | B5: Salesperson 4 | C5: Mid-Market | D5: South | E5: Vikas
A6: SP005 | B6: Salesperson 5 | C6: Mid-Market | D6: South | E6: Vikas
A7: SP006 | B7: Salesperson 6 | C7: Mid-Market | D7: South | E7: Amit
A8: SP007 | B8: Salesperson 7 | C8: SMB | D8: East | E8: Rohit
A9: SP008 | B9: Salesperson 8 | C9: Mid-Market | D9: Central | E9: Neha
A10: SP009 | B10: Salesperson 9 | C10: Mid-Market | D10: North | E10: Amit
A11: SP010 | B11: Salesperson 10 | C11: Mid-Market | D11: West | E11: Neha
A12: SP011 | B12: Salesperson 11 | C12: Mid-Market | D12: North | E12: Neha
... A51: SP050 | B51: Salesperson 50 | C51: Enterprise | D51: East | E51: Neha

Sheet Targets
A1: Month | B1: Salesperson_ID | C1: Target
A2: 46023 | B2: SP016 | C2: 593518
A3: 46054 | B3: SP008 | C3: 675774
A4: 46082 | B4: SP004 | C4: 593271
A5: 46113 | B5: SP040 | C5: 311317
A6: 46143 | B6: SP004 | C6: 339789
A7: 46174 | B7: SP025 | C7: 589593
A8: 46204 | B8: SP003 | C8: 490843
A9: 46235 | B9: SP032 | C9: 273686
A10: 46266 | B10: SP003 | C10: 267661
A11: 46296 | B11: SP027 | C11: 244247
A12: 46327 | B12: SP029 | C12: 445121
A13: 46357 | B13: SP032 | C13: 347820
... A51: 47515 | B51: SP015 | C51: 599384

Sheet Date
A1: Date | B1: Year | C1: Month | D1: Month_Number | E1: Quarter | F1: Week_Number | G1: Day
A2: 46023 | B2: 2026 | C2: January | D2: 1 | E2: Q1 | F2: 1 | G2: Thursday
A3: 46024 | B3: 2026 | C3: January | D3: 1 | E3: Q1 | F3: 1 | G3: Friday
A4: 46025 | B4: 2026 | C4: January | D4: 1 | E4: Q1 | F4: 1 | G4: Saturday
A5: 46026 | B5: 2026 | C5: January | D5: 1 | E5: Q1 | F5: 1 | G5: Sunday
A6: 46027 | B6: 2026 | C6: January | D6: 1 | E6: Q1 | F6: 2 | G6: Monday
A7: 46028 | B7: 2026 | C7: January | D7: 1 | E7: Q1 | F7: 2 | G7: Tuesday
A8: 46029 | B8: 2026 | C8: January | D8: 1 | E8: Q1 | F8: 2 | G8: Wednesday
A9: 46030 | B9: 2026 | C9: January | D9: 1 | E9: Q1 | F9: 2 | G9: Thursday
A10: 46031 | B10: 2026 | C10: January | D10: 1 | E10: Q1 | F10: 2 | G10: Friday
A11: 46032 | B11: 2026 | C11: January | D11: 1 | E11: Q1 | F11: 2 | G11: Saturday
A12: 46033 | B12: 2026 | C12: January | D12: 1 | E12: Q1 | F12: 2 | G12: Sunday
A13: 46034 | B13: 2026 | C13: January | D13: 1 | E13: Q1 | F13: 3 | G13: Monday
... A51: 46072 | B51: 2026 | C51: February | D51: 2 | E51: Q1 | F51: 8 | G51: Thursday

Sheet Excel_Tasks
A1: Level | B1: Task | C1: Excel Skill | D1: Answers | E1: Status
A2: Basics | B2: Format each dataset as an Excel Table. | C2: Tables
A3: Basics | B3: Sort Sales by Revenue largest to smallest. | C3: Sort | E3: Done
A4: Basics | B4: Filter only Won deals. | C4: Filter | E4: Done
A5: Basics | B5: Find Total Revenue. | C5: SUM | D5: =SUM(Sales!I2:I51) -> 5145784.5 | E5: Done
A6: Basics | B6: Find Average Revenue. | C6: AVERAGE | D6: =AVERAGE(Sales!I2:I51) -> 102915.69 | E6: Done
C7: MIN | D7: =MIN(Sales!I2:I51) -> 0 | E7: Done
A8: Basics | B8: Find highest and lowest Revenue. | C8: MAX | D8: =MAX(Sales!I2:I51) -> 538498 | E8: done
A9: Basics | B9: Count total Sales IDs. | C9: COUNT | D9: =COUNT(Sales!I2:I51) -> 50 | E9: done
C10: COUNTA | D10: =COUNTA(Sales!I2:I51) -> 50 | E10: done
C11: WON | D11: =COUNTIF(Sales!F2:F51, "Won") -> 29 | E11: done
C12: LOST | D12: =COUNTIF(Sales!F2:F51,"Lost") -> 14 | E12: done
A13: Basics | B13: Count Won, Lost and Pending deals. | C13: COUNTIF/Pending deals | D13: =COUNTIF(Sales!F2:F51,"Pending") -> 7 | E13: done
A14: Basics | B14: Find Won Revenue. | C14: SUMIFS | D14: =SUMIF(Sales!F2:F51, "Won", Sales!I2:I51) -> 5145784.5 | E14: done
A15: Lookup | B15: Use XLOOKUP to bring Product Name into Sales. | C15: XLOOKUP | D15: =_xlfn.XLOOKUP(Sales!#REF!, Products!A2:A51, Products!B2:B51) -> #REF! | E15: Done
A16: Lookup | B16: Use XLOOKUP to bring Product Price into Sales. | C16: XLOOKUP | D16: =_xlfn.XLOOKUP(Sales!#REF!,Products!A2:A51,Products!D2:D51) -> #REF! | E16: Done
A17: Lookup | B17: Use XLOOKUP to bring Customer Segment into Sales. | C17: XLOOKUP | D17: =_xlfn.XLOOKUP(Sales!C4, Customers!A2:A51, Customers!D2:D51) -> Enterprise | E17: Done
A18: Lookup | B18: Use XLOOKUP to bring Salesperson Name into Sales. | C18: XLOOKUP | D18: =_xlfn.XLOOKUP(Sales!E4, Salespeople!A2:A51, Salespeople!B2:B51) -> Salesperson 18 | E18: Done
A19: Lookup | B19: Use INDEX + MATCH to find Customer Industry. | C19: INDEX/MATCH | D19: =INDEX(Customers!$C$2:$C$9,MATCH("C008",Customers!$A$2:$A$9,0)) -> Healthcare | E19: Done
A20: Lookup | B20: Calculate Gross Sales using Quantity × Price. | C20: Arithmetic | D20: =Sales!G5*Products!D18 -> 228215 | E20: done
A21: Lookup | B21: Calculate Net Revenue after Discount. | C21: Arithmetic | D21: =Sales!#REF!-Sales!#REF!*Sales!#REF!/100 -> #REF! | E21: done
C22: High | D22: =IF(Sales!I4>200000,"High Value", "Normal Value") -> Normal Value | E22: done
A23: Logic | B23: Use IF to classify deals as High/Normal value. | C23: IF/Normal | D23: =IF(Sales!I7<200000,"High Value", "Normal Value") -> High Value | E23: done
A24: Logic | B24: Use IFS to classify revenue as Low/Medium/High. | C24: IFS | D24: {=_xlfn.IFS(Sales!#REF!<25000,"Low", Sales!#REF!<=500000,"Medium", Sales!#REF!>500000,"High")} -> #REF! | E24: done
A25: Logic | B25: Use AND to find Won deals above ₹50,000. | C25: AND | D25: =IF(AND(Sales!F5="WON",Sales!F5>50000),"Yes","No") -> Yes | E25: done
A26: Logic | B26: Use OR to find North or West region records. | C26: OR | D26: =IF(OR(Sales!D5 ="North", Sales!D5 = "West"), "Yes","No") -> No | E26: done
A27: Logic | B27: Use IFERROR to handle missing lookups. | C27: IFERROR | D27: =IFERROR(_xlfn.XLOOKUP(Sales!#REF!, Products!A2:A51, Products!B2:B53),"NOT FOUND") -> NOT FOUND | E27: done
A28: Conditional | B28: Use SUMIFS for Won Revenue by region. | C28: SUMIFS | D28: =SUMIFS(Sales!I2:I51, Sales!F2:F51,"WON", Salespeople!D2:D51,"North") -> 853711.45 | E28: done
A29: Conditional | B29: Use COUNTIFS for Won deals by region. | C29: COUNTIFS | D29: =COUNTIFS( Sales!F2:F51,"WON", Salespeople!D2:D51,"North") -> 5 | E29: done
A30: Conditional | B30: Use AVERAGEIFS for average Won deal value by segment. | C30: WON | D30: =AVERAGEIFS(Sales!I2:I51, Sales!F2:F51, "Won", Customers!D2:D51,"Mid-Market") -> 127360.97 | E30: done
A31: Text | B31: Clean names with TRIM. | C31: TRIM | D31: =TRIM(Customers!D6) -> Mid- Market | E31: done
A32: Text | B32: Standardize names with PROPER. | C32: PROPER | D32: =PROPER(Customers!F2) -> Rajasthan | E32: done
A33: Text | B33: Extract text using LEFT and SEARCH. | C33: LEFT/SEARCH | D33: =LEFT(SEARCH("s",Customers!F2)) -> 5 | E33: done
A34: Text | B34: Combine two fields using TEXTJOIN. | C34: TEXTJOIN | D34: =_xlfn.TEXTJOIN(" ", TRUE, Products!C2,Salespeople!E5) -> HR Vikas | E34: done
A35: Text | B35: Count characters using LEN. | C35: LEN | D35: =LEN(Customers!F2) -> 9 | E35: done
C36: Moths | D36: =MONTH(Sales!#REF!) -> #REF! | E36: done
A37: Dates | B37: Extract Year and Month from Date. | C37: YEAR/MONTH | D37: =YEAR(Sales!#REF!) -> #REF! | E37: done
A38: Dates | B38: Create a Month-Year field. | C38: TEXT | D38: =TEXT(Sales!#REF!,"mmm-yyyy") -> #REF! | E38: done
A39: Dates | B39: Count sales by month. | C39: COUNTIFS | D39: =COUNTIFS(Sales!B2:B51,">="&DATE(2026,2,1),Sales!B2:B51,"<"&DATE(2026,3,1)) -> 9 | E39: done
A40: Dates | B40: Calculate monthly Won Revenue. | C40: SUMIFS | D40: =SUMIFS(Sales!I2:I51,Sales!F2:F51,"Won",Sales!B2:B51,">="&DATE(2026,3,1),Sales!B2:B51,"<"&DATE(2026,4,1)) -> 274946.75 | E40: done
...
